Workbook

Sheet Contenido
B1: SUPERINTENDENCIA DE BANCOS DEL ECUADOR INTENDENCIA NACIONAL DE RIESGOS Y ESTUDIOS DIRECCIÓN DE ESTUDIOS Y GESTIÓN DE LA INFORMACIÓN SUBDIRECCIÓN DE ESTADÍSTICAS Y ESTUDIOS
B3: ESTADÍSTICAS DE RETIROS DE DINERO EN EFECTIVO SOBRE CUENTAS DE AHORRO EN CANALES PROPIOS DE LA ENTIDAD
B4: Enero a Diciembre 2020
C6: TABLA DE CONTENIDO
C8: =+'SECCIÓN I'!B8 -> SECCIÓN I: RETIROS DE DINERO EN GENERAL
C9: 1.1 Evolución de Transacciones y Montos de Retiros de Dinero
C11: =+'SECCIÓN II'!B8 -> SECCIÓN II: RETIROS DE DINERO POR ENTIDAD FINANCIERA
C12: 2.1 Evolución de Transacciones de Retiros de Dinero por Entidad Financiera
C13: 2.2 Evolución del Monto de Retiros de Dinero por Entidad Financiera
C14: 2.3 Evolución del Monto Promedio de Retiros de Dinero por Entidad Financiera
C15: 2.4 Resumen Anual de Transacciones, Monto de Retiros y Monto Promedio de Retiros de Dinero por Entidad Financiera
C17: =+'SECCIÓN III'!B8 -> SECCIÓN III: RETIROS DE DINERO POR CANALES
C18: 3.1 Evolución de Transacciones de Retiros de Dinero por Canales
C19: 3.2 Evolución del Monto de Retiros de Dinero por Canales
C20: 3.3 Evolución del Monto Promedio de Retiros de Dinero por Canales
C21: 3.4 Resumen Anual de Transacciones, Monto de Retiros y Monto Promedio de Retiros de Dinero por Canales
C23: =+'SECCIÓN IV'!B8 -> SECCIÓN IV: RETIROS DE DINERO POR PROVINCIA
C24: 4.1 Evolución de Transacciones de Retiros de Dinero por Provincia
C25: 4.2 Evolución del Monto de Retiros de Dinero por Provincia
C26: 4.3 Evolución del Monto Promedio de Retiros de Dinero por Provincia
C27: 4.4 Resumen Anual de Transacciones, Monto de Retiros y Monto Promedio de Retiros de Dinero por Provincia
C29: =+'SECCIÓN V'!B8 -> SECCIÓN V: RETIROS DE DINERO POR ORDENANTE
C30: 5.1 Evolución de Transacciones de Retiros de Dinero por Ordenante
C31: 5.2 Evolución del Monto de Retiros de Dinero por Ordenante
C32: 5.3 Evolución del Monto Promedio de Retiros de Dinero por Ordenante
C33: 5.4 Resumen Anual de Transacciones, Monto de Retiros y Monto Promedio de Retiros de Dinero por Ordenante
C35: =+'SECCIÓN VI'!B8 -> SECCIÓN VI: RETIROS DE DINERO POR ENTIDAD FINANCIERA POR CANAL
C36: 6.1 Evolución de Transacciones de Retiros de Dinero por Entidad Financiera por Canal
C37: 6.2 Evolución del Monto de Retiros de Dinero por Entidad Financiera por Canal
C38: 6.3. Evolución del Monto Promedio de Retiros de Dinero por Entidad Financiera por Canal
C40: =+'SECCIÓN VII'!B8 -> SECCIÓN VII: RETIROS DE DINERO POR ENTIDAD FINANCIERA POR PROVINCIA
C41: 7.1 Evolución de Transacciones de Retiros de Dinero por Entidad Financiera por Provincia
C42: 7.2 Evolución del Monto de Retiros de Dinero por Entidad Financiera por Provincia
C43: 7.3. Evolución del Monto Promedio de Retiros de Dinero por Entidad Financiera por Provincia
C45: =+'SECCIÓN VIII'!B8 -> SECCIÓN VIII: RETIROS DE DINERO POR ENTIDAD FINANCIERA POR ORDENANTE
C46: 8.1 Evolución de Transacciones de Retiros de Dinero por Entidad Financiera por Ordenante
C47: 8.2 Evolución del Monto de Retiros de Dinero por Entidad Financiera por Ordenante
C48: 8.3. Evolución del Monto Promedio de Retiros de Dinero por Entidad Financiera por Ordenante
C50: =+'SECCIÓN IX'!B8 -> SECCIÓN IX: RETIROS DE DINERO POR CANAL POR PROVINCIA
C51: 9.1 Evolución de Transacciones de Retiros de Dinero por Canal por Provincia
...

Sheet Retiros de Dinero Ene-Dic 2016
B1: SUPERINTENDENCIA DE BANCOS DEL ECUADOR DIRECCIÓN NACIONAL DE ESTUDIOS E INFORMACIÓN SUBDIRECCIÓN DE ADMINISTRACIÓN DE SERVICIOS
B5: ESTADÍSTICAS DE RETIROS DE DINERO EN EFECTIVO SOBRE CUENTAS DE AHORRO EN CANALES PROPIOS DE LA ENTIDAD
B6: Enero - Diciembre 2016
B7: Fecha de publicación: Febrero 2017
B10: SECCIÓN I: RETIROS DE DINERO EN GENERAL
B12: 1.1 Evolución de Transacciones y Montos de Retiros de Dinero
B15: Tipo de Entidad | C15: enero | D15: febrero | E15: marzo | F15: abril | G15: mayo | H15: junio | I15: julio | J15: agosto | K15: septiembre | L15: octubre | M15: noviembre | N15: diciembre | O15: Total | P15: Promedio
B16: Número de Retiros | C16: =+#REF! -> #REF! | D16: =+#REF! -> #REF! | E16: =+#REF! -> #REF! | F16: =+#REF! -> #REF! | G16: =+#REF! -> #REF! | H16: =+#REF! -> #REF! | I16: =+#REF! -> #REF! | J16: =+#REF! -> #REF! | ... N16: =+#REF! -> #REF! | O16: =SUM(C16:N16) -> #REF! | P16: =+AVERAGE(C16:N16) -> #REF!
B17: Monto de Retiros | C17: =+#REF! -> #REF! | D17: =+#REF! -> #REF! | E17: =+#REF! -> #REF! | F17: =+#REF! -> #REF! | G17: =+#REF! -> #REF! | H17: =+#REF! -> #REF! | I17: =+#REF! -> #REF! | J17: =+#REF! -> #REF! | ... N17: =+#REF! -> #REF! | O17: =SUM(C17:N17) -> #REF! | P17: =+AVERAGE(C17:N17) -> #REF!
B18: Monto Promedio por Retiro | C18: =+C17/C16 -> #REF! | D18: =+D17/D16 -> #REF! | E18: =+E17/E16 -> #REF! | F18: =+F17/F16 -> #REF! | G18: =+G17/G16 -> #REF! | H18: =+H17/H16 -> #REF! | I18: =+I17/I16 -> #REF! | J18: =+J17/J16 -> #REF! | ... P18: =+P17/P16 -> #REF!
B38: SECCIÓN II: RETIROS DE DINERO POR ENTIDAD FINANCIERA
B40: 2.1 Evolución de Transacciones de Retiros de Dinero por Entidad Financiera
B43: Entidad Financiera | C43: enero | D43: febrero | E43: marzo | F43: abril | G43: mayo | H43: junio | I43: julio | J43: agosto | K43: septiembre | L43: octubre | M43: noviembre | N43: diciembre | O43: Total | P43: Promedio | Q43: % Número de Retiros | BA43: Entidad Financiera | BB43: enero | BC43: febrero | BD43: marzo | BE43: abril | BF43: mayo | BG43: junio | BH43: julio | BI43: agosto | BJ43: septiembre | BK43: octubre | BL43: noviembre | BM43: diciembre | BN43: Total
B44: =+#REF! -> #REF! | C44: =+#REF! -> #REF! | D44: =+#REF! -> #REF! | E44: =+#REF! -> #REF! | F44: =+#REF! -> #REF! | G44: =+#REF! -> #REF! | H44: =+#REF! -> #REF! | I44: =+#REF! -> #REF! | ... N44: =+#REF! -> #REF! | O44: =SUM(C44:N44) -> #REF! | P44: =+AVERAGE(C44:N44) -> #REF! | Q44: =+O44/$O$78 -> #REF! | BA44: =+B44 -> #REF! | BB44: =+C44 -> #REF! | BC44: =+D44 -> #REF! | BD44: =+E44 -> #REF! | BE44: =+F44 -> #REF! | BF44: =+G44 -> #REF! | BG44: =+H44 -> #REF! | BH44: =+I44 -> #REF! | ... BN44: =+O44 -> #REF!
B45: =+#REF! -> #REF! | C45: =+#REF! -> #REF! | D45: =+#REF! -> #REF! | E45: =+#REF! -> #REF! | F45: =+#REF! -> #REF! | G45: =+#REF! -> #REF! | H45: =+#REF! -> #REF! | I45: =+#REF! -> #REF! | ... N45: =+#REF! -> #REF! | O45: =SUM(C45:N45) -> #REF! | P45: =+AVERAGE(C45:N45) -> #REF! | Q45: =+O45/$O$78 -> #REF! | BA45: =+B45 -> #REF! | BB45: =+C45 -> #REF! | BC45: =+D45 -> #REF! | BD45: =+E45 -> #REF! | BE45: =+F45 -> #REF! | BF45: =+G45 -> #REF! | BG45: =+H45 -> #REF! | BH45: =+I45 -> #REF! | ... BN45: =+O45 -> #REF!
B46: =+#REF! -> #REF! | C46: =+#REF! -> #REF! | D46: =+#REF! -> #REF! | E46: =+#REF! -> #REF! | F46: =+#REF! -> #REF! | G46: =+#REF! -> #REF! | H46: =+#REF! -> #REF! | I46: =+#REF! -> #REF! | ... N46: =+#REF! -> #REF! | O46: =SUM(C46:N46) -> #REF! | P46: =+AVERAGE(C46:N46) -> #REF! | Q46: =+O46/$O$78 -> #REF! | BA46: =+B46 -> #REF! | BB46: =+C46 -> #REF! | BC46: =+D46 -> #REF! | BD46: =+E46 -> #REF! | BE46: =+F46 -> #REF! | BF46: =+G46 -> #REF! | BG46: =+H46 -> #REF! | BH46: =+I46 -> #REF! | ... BN46: =+O46 -> #REF!
B47: =+#REF! -> #REF! | C47: =+#REF! -> #REF! | D47: =+#REF! -> #REF! | E47: =+#REF! -> #REF! | F47: =+#REF! -> #REF! | G47: =+#REF! -> #REF! | H47: =+#REF! -> #REF! | I47: =+#REF! -> #REF! | ... N47: =+#REF! -> #REF! | O47: =SUM(C47:N47) -> #REF! | P47: =+AVERAGE(C47:N47) -> #REF! | Q47: =+O47/$O$78 -> #REF! | BA47: =+B47 -> #REF! | BB47: =+C47 -> #REF! | BC47: =+D47 -> #REF! | BD47: =+E47 -> #REF! | BE47: =+F47 -> #REF! | BF47: =+G47 -> #REF! | BG47: =+H47 -> #REF! | BH47: =+I47 -> #REF! | ... BN47: =+O47 -> #REF!
B48: =+#REF! -> #REF! | C48: =+#REF! -> #REF! | D48: =+#REF! -> #REF! | E48: =+#REF! -> #REF! | F48: =+#REF! -> #REF! | G48: =+#REF! -> #REF! | H48: =+#REF! -> #REF! | I48: =+#REF! -> #REF! | ... N48: =+#REF! -> #REF! | O48: =SUM(C48:N48) -> #REF! | P48: =+AVERAGE(C48:N48) -> #REF! | Q48: =+O48/$O$78 -> #REF! | BA48: =+B48 -> #REF! | BB48: =+C48 -> #REF! | BC48: =+D48 -> #REF! | BD48: =+E48 -> #REF! | BE48: =+F48 -> #REF! | BF48: =+G48 -> #REF! | BG48: =+H48 -> #REF! | BH48: =+I48 -> #REF! | ... BN48: =+O48 -> #REF!
B49: =+#REF! -> #REF! | C49: =+#REF! -> #REF! | D49: =+#REF! -> #REF! | E49: =+#REF! -> #REF! | F49: =+#REF! -> #REF! | G49: =+#REF! -> #REF! | H49: =+#REF! -> #REF! | I49: =+#REF! -> #REF! | ... N49: =+#REF! -> #REF! | O49: =SUM(C49:N49) -> #REF! | P49: =+AVERAGE(C49:N49) -> #REF! | Q49: =+O49/$O$78 -> #REF! | BA49: Resto de Entidades Financieras | BB49: =SUM(BB50:BB78) -> #REF! | BC49: =SUM(BC50:BC78) -> #REF! | BD49: =SUM(BD50:BD78) -> #REF! | BE49: =SUM(BE50:BE78) -> #REF! | BF49: =SUM(BF50:BF78) -> #REF! | BG49: =SUM(BG50:BG78) -> #REF! | BH49: =SUM(BH50:BH78) -> #REF! | BI49: =SUM(BI50:BI78) -> #REF! | ... BN49: =SUM(BN50:BN78) -> #REF!
B50: =+#REF! -> #REF! | C50: =+#REF! -> #REF! | D50: =+#REF! -> #REF! | E50: =+#REF! -> #REF! | F50: =+#REF! -> #REF! | G50: =+#REF! -> #REF! | H50: =+#REF! -> #REF! | I50: =+#REF! -> #REF! | ... N50: =+#REF! -> #REF! | O50: =SUM(C50:N50) -> #REF! | P50: =+AVERAGE(C50:N50) -> #REF! | Q50: =+O50/$O$78 -> #REF! | BA50: =+B49 -> #REF! | BB50: =+C49 -> #REF! | BC50: =+D49 -> #REF! | BD50: =+E49 -> #REF! | BE50: =+F49 -> #REF! | BF50: =+G49 -> #REF! | BG50: =+H49 -> #REF! | BH50: =+I49 -> #REF! | ... BN50: =+O49 -> #REF!
B51: =+#REF! -> #REF! | C51: =+#REF! -> #REF! | D51: =+#REF! -> #REF! | E51: =+#REF! -> #REF! | F51: =+#REF! -> #REF! | G51: =+#REF! -> #REF! | H51: =+#REF! -> #REF! | I51: =+#REF! -> #REF! | ... N51: =+#REF! -> #REF! | O51: =SUM(C51:N51) -> #REF! | P51: =+AVERAGE(C51:N51) -> #REF! | Q51: =+O51/$O$78 -> #REF! | BA51: =+B50 -> #REF! | BB51: =+C50 -> #REF! | BC51: =+D50 -> #REF! | BD51: =+E50 -> #REF! | BE51: =+F50 -> #REF! | BF51: =+G50 -> #REF! | BG51: =+H50 -> #REF! | BH51: =+I50 -> #REF! | ... BN51: =+O50 -> #REF!
B52: =+#REF! -> #REF! | C52: =+#REF! -> #REF! | D52: =+#REF! -> #REF! | E52: =+#REF! -> #REF! | F52: =+#REF! -> #REF! | G52: =+#REF! -> #REF! | H52: =+#REF! -> #REF! | I52: =+#REF! -> #REF! | ... N52: =+#REF! -> #REF! | O52: =SUM(C52:N52) -> #REF! | P52: =+AVERAGE(C52:N52) -> #REF! | Q52: =+O52/$O$78 -> #REF! | BA52: =+B51 -> #REF! | BB52: =+C51 -> #REF! | BC52: =+D51 -> #REF! | BD52: =+E51 -> #REF! | BE52: =+F51 -> #REF! | BF52: =+G51 -> #REF! | BG52: =+H51 -> #REF! | BH52: =+I51 -> #REF! | ... BN52: =+O51 -> #REF!
B53: =+#REF! -> #REF! | C53: =+#REF! -> #REF! | D53: =+#REF! -> #REF! | E53: =+#REF! -> #REF! | F53: =+#REF! -> #REF! | G53: =+#REF! -> #REF! | H53: =+#REF! -> #REF! | I53: =+#REF! -> #REF! | ... N53: =+#REF! -> #REF! | O53: =SUM(C53:N53) -> #REF! | P53: =+AVERAGE(C53:N53) -> #REF! | Q53: =+O53/$O$78 -> #REF! | BA53: =+B52 -> #REF! | BB53: =+C52 -> #REF! | BC53: =+D52 -> #REF! | BD53: =+E52 -> #REF! | BE53: =+F52 -> #REF! | BF53: =+G52 -> #REF! | BG53: =+H52 -> #REF! | BH53: =+I52 -> #REF! | ... BN53: =+O52 -> #REF!
B54: =+#REF! -> #REF! | C54: =+#REF! -> #REF! | D54: =+#REF! -> #REF! | E54: =+#REF! -> #REF! | F54: =+#REF! -> #REF! | G54: =+#REF! -> #REF! | H54: =+#REF! -> #REF! | I54: =+#REF! -> #REF! | ... N54: =+#REF! -> #REF! | O54: =SUM(C54:N54) -> #REF! | P54: =+AVERAGE(C54:N54) -> #REF! | Q54: =+O54/$O$78 -> #REF! | BA54: =+B53 -> #REF! | BB54: =+C53 -> #REF! | BC54: =+D53 -> #REF! | BD54: =+E53 -> #REF! | BE54: =+F53 -> #REF! | BF54: =+G53 -> #REF! | BG54: =+H53 -> #REF! | BH54: =+I53 -> #REF! | ... BN54: =+O53 -> #REF!
B55: =+#REF! -> #REF! | C55: =+#REF! -> #REF! | D55: =+#REF! -> #REF! | E55: =+#REF! -> #REF! | F55: =+#REF! -> #REF! | G55: =+#REF! -> #REF! | H55: =+#REF! -> #REF! | I55: =+#REF! -> #REF! | ... N55: =+#REF! -> #REF! | O55: =SUM(C55:N55) -> #REF! | P55: =+AVERAGE(C55:N55) -> #REF! | Q55: =+O55/$O$78 -> #REF! | BA55: =+B54 -> #REF! | BB55: =+C54 -> #REF! | BC55: =+D54 -> #REF! | BD55: =+E54 -> #REF! | BE55: =+F54 -> #REF! | BF55: =+G54 -> #REF! | BG55: =+H54 -> #REF! | BH55: =+I54 -> #REF! | ... BN55: =+O54 -> #REF!
B56: =+#REF! -> #REF! | C56: =+#REF! -> #REF! | D56: =+#REF! -> #REF! | E56: =+#REF! -> #REF! | F56: =+#REF! -> #REF! | G56: =+#REF! -> #REF! | H56: =+#REF! -> #REF! | I56: =+#REF! -> #REF! | ... N56: =+#REF! -> #REF! | O56: =SUM(C56:N56) -> #REF! | P56: =+AVERAGE(C56:N56) -> #REF! | Q56: =+O56/$O$78 -> #REF! | BA56: =+B55 -> #REF! | BB56: =+C55 -> #REF! | BC56: =+D55 -> #REF! | BD56: =+E55 -> #REF! | BE56: =+F55 -> #REF! | BF56: =+G55 -> #REF! | BG56: =+H55 -> #REF! | BH56: =+I55 -> #REF! | ... BN56: =+O55 -> #REF!
B57: =+#REF! -> #REF! | C57: =+#REF! -> #REF! | D57: =+#REF! -> #REF! | E57: =+#REF! -> #REF! | F57: =+#REF! -> #REF! | G57: =+#REF! -> #REF! | H57: =+#REF! -> #REF! | I57: =+#REF! -> #REF! | ... N57: =+#REF! -> #REF! | O57: =SUM(C57:N57) -> #REF! | P57: =+AVERAGE(C57:N57) -> #REF! | Q57: =+O57/$O$78 -> #REF! | BA57: =+B56 -> #REF! | BB57: =+C56 -> #REF! | BC57: =+D56 -> #REF! | BD57: =+E56 -> #REF! | BE57: =+F56 -> #REF! | BF57: =+G56 -> #REF! | BG57: =+H56 -> #REF! | BH57: =+I56 -> #REF! | ... BN57: =+O56 -> #REF!
B58: =+#REF! -> #REF! | C58: =+#REF! -> #REF! | D58: =+#REF! -> #REF! | E58: =+#REF! -> #REF! | F58: =+#REF! -> #REF! | G58: =+#REF! -> #REF! | H58: =+#REF! -> #REF! | I58: =+#REF! -> #REF! | ... N58: =+#REF! -> #REF! | O58: =SUM(C58:N58) -> #REF! | P58: =+AVERAGE(C58:N58) -> #REF! | Q58: =+O58/$O$78 -> #REF! | BA58: =+B57 -> #REF! | BB58: =+C57 -> #REF! | BC58: =+D57 -> #REF! | BD58: =+E57 -> #REF! | BE58: =+F57 -> #REF! | BF58: =+G57 -> #REF! | BG58: =+H57 -> #REF! | BH58: =+I57 -> #REF! | ... BN58: =+O57 -> #REF!
B59: =+#REF! -> #REF! | C59: =+#REF! -> #REF! | D59: =+#REF! -> #REF! | E59: =+#REF! -> #REF! | F59: =+#REF! -> #REF! | G59: =+#REF! -> #REF! | H59: =+#REF! -> #REF! | I59: =+#REF! -> #REF! | ... N59: =+#REF! -> #REF! | O59: =SUM(C59:N59) -> #REF! | P59: =+AVERAGE(C59:N59) -> #REF! | Q59: =+O59/$O$78 -> #REF! | BA59: =+B58 -> #REF! | BB59: =+C58 -> #REF! | BC59: =+D58 -> #REF! | BD59: =+E58 -> #REF! | BE59: =+F58 -> #REF! | BF59: =+G58 -> #REF! | BG59: =+H58 -> #REF! | BH59: =+I58 -> #REF! | ... BN59: =+O58 -> #REF!
B60: =+#REF! -> #REF! | C60: =+#REF! -> #REF! | D60: =+#REF! -> #REF! | E60: =+#REF! -> #REF! | F60: =+#REF! -> #REF! | G60: =+#REF! -> #REF! | H60: =+#REF! -> #REF! | I60: =+#REF! -> #REF! | ... N60: =+#REF! -> #REF! | O60: =SUM(C60:N60) -> #REF! | P60: =+AVERAGE(C60:N60) -> #REF! | Q60: =+O60/$O$78 -> #REF! | BA60: =+B59 -> #REF! | BB60: =+C59 -> #REF! | BC60: =+D59 -> #REF! | BD60: =+E59 -> #REF! | BE60: =+F59 -> #REF! | BF60: =+G59 -> #REF! | BG60: =+H59 -> #REF! | BH60: =+I59 -> #REF! | ... BN60: =+O59 -> #REF!
B61: =+#REF! -> #REF! | C61: =+#REF! -> #REF! | D61: =+#REF! -> #REF! | E61: =+#REF! -> #REF! | F61: =+#REF! -> #REF! | G61: =+#REF! -> #REF! | H61: =+#REF! -> #REF! | I61: =+#REF! -> #REF! | ... N61: =+#REF! -> #REF! | O61: =SUM(C61:N61) -> #REF! | P61: =+AVERAGE(C61:N61) -> #REF! | Q61: =+O61/$O$78 -> #REF! | BA61: =+B60 -> #REF! | BB61: =+C60 -> #REF! | BC61: =+D60 -> #REF! | BD61: =+E60 -> #REF! | BE61: =+F60 -> #REF! | BF61: =+G60 -> #REF! | BG61: =+H60 -> #REF! | BH61: =+I60 -> #REF! | ... BN61: =+O60 -> #REF!
... B77: =+#REF! -> #REF! | C77: =+#REF! -> #REF! | D77: =+#REF! -> #REF! | E77: =+#REF! -> #REF! | F77: =+#REF! -> #REF! | G77: =+#REF! -> #REF! | H77: =+#REF! -> #REF! | I77: =+#REF! -> #REF! | ... N77: =+#REF! -> #REF! | O77: =SUM(C77:N77) -> #REF! | P77: =+AVERAGE(C77:N77) -> #REF! | Q77: =+O77/$O$78 -> #REF! | BA77: =+B76 -> #REF! | BB77: =+C76 -> #REF! | BC77: =+D76 -> #REF! | BD77: =+E76 -> #REF! | BE77: =+F76 -> #REF! | BF77: =+G76 -> #REF! | BG77: =+H76 -> #REF! | BH77: =+I76 -> #REF! | ... BN77: =+O76 -> #REF!
B78: Total | C78: =SUM(C44:C77) -> #REF! | D78: =SUM(D44:D77) -> #REF! | E78: =SUM(E44:E77) -> #REF! | F78: =SUM(F44:F77) -> #REF! | G78: =SUM(G44:G77) -> #REF! | H78: =SUM(H44:H77) -> #REF! | I78: =SUM(I44:I77) -> #REF! | J78: =SUM(J44:J77) -> #REF! | ... N78: =SUM(N44:N77) -> #REF! | O78: =SUM(C78:N78) -> #REF! | P78: =+AVERAGE(C78:N78) -> #REF! | Q78: =+O78/$O$78 -> #REF! | BA78: =+B77 -> #REF! | BB78: =+C77 -> #REF! | BC78: =+D77 -> #REF! | BD78: =+E77 -> #REF! | BE78: =+F77 -> #REF! | BF78: =+G77 -> #REF! | BG78: =+H77 -> #REF! | BH78: =+I77 -> #REF! | ... BN78: =+O77 -> #REF!
BA79: =+B78 -> Total | BB79: =+C78 -> #REF! | BC79: =+D78 -> #REF! | BD79: =+E78 -> #REF! | BE79: =+F78 -> #REF! | BF79: =+G78 -> #REF! | BG79: =+H78 -> #REF! | BH79: =+I78 -> #REF! | ... BN79: =+O78 -> #REF!
B103: 2.2 Evolución del Monto de Retiros de Dinero por Entidad Financiera
B106: Entidad Financiera | C106: enero | D106: febrero | E106: marzo | F106: abril | G106: mayo | H106: junio | I106: julio | J106: agosto | K106: septiembre | L106: octubre | M106: noviembre | N106: diciembre | O106: Total | P106: Promedio | Q106: % Monto por Retiros | BA106: Entidad Financiera | BB106: enero | BC106: febrero | BD106: marzo | BE106: abril | BF106: mayo | BG106: junio | BH106: julio | BI106: agosto | BJ106: septiembre | BK106: octubre | BL106: noviembre | BM106: diciembre | BN106: Total
B107: =+#REF! -> #REF! | C107: =+#REF! -> #REF! | D107: =+#REF! -> #REF! | E107: =+#REF! -> #REF! | F107: =+#REF! -> #REF! | G107: =+#REF! -> #REF! | H107: =+#REF! -> #REF! | I107: =+#REF! -> #REF! | ... N107: =+#REF! -> #REF! | O107: =SUM(C107:N107) -> #REF! | P107: =+AVERAGE(C107:N107) -> #REF! | Q107: =+O107/$O$141 -> #REF! | BA107: =+B107 -> #REF! | BB107: =+C107 -> #REF! | BC107: =+D107 -> #REF! | BD107: =+E107 -> #REF! | BE107: =+F107 -> #REF! | BF107: =+G107 -> #REF! | BG107: =+H107 -> #REF! | BH107: =+I107 -> #REF! | ... BN107: =+O107 -> #REF!
B108: =+#REF! -> #REF! | C108: =+#REF! -> #REF! | D108: =+#REF! -> #REF! | E108: =+#REF! -> #REF! | F108: =+#REF! -> #REF! | G108: =+#REF! -> #REF! | H108: =+#REF! -> #REF! | I108: =+#REF! -> #REF! | ... N108: =+#REF! -> #REF! | O108: =SUM(C108:N108) -> #REF! | P108: =+AVERAGE(C108:N108) -> #REF! | Q108: =+O108/$O$141 -> #REF! | BA108: =+B108 -> #REF! | BB108: =+C108 -> #REF! | BC108: =+D108 -> #REF! | BD108: =+E108 -> #REF! | BE108: =+F108 -> #REF! | BF108: =+G108 -> #REF! | BG108: =+H108 -> #REF! | BH108: =+I108 -> #REF! | ... BN108: =+O108 -> #REF!
B109: =+#REF! -> #REF! | C109: =+#REF! -> #REF! | D109: =+#REF! -> #REF! | E109: =+#REF! -> #REF! | F109: =+#REF! -> #REF! | G109: =+#REF! -> #REF! | H109: =+#REF! -> #REF! | I109: =+#REF! -> #REF! | ... N109: =+#REF! -> #REF! | O109: =SUM(C109:N109) -> #REF! | P109: =+AVERAGE(C109:N109) -> #REF! | Q109: =+O109/$O$141 -> #REF! | BA109: =+B109 -> #REF! | BB109: =+C109 -> #REF! | BC109: =+D109 -> #REF! | BD109: =+E109 -> #REF! | BE109: =+F109 -> #REF! | BF109: =+G109 -> #REF! | BG109: =+H109 -> #REF! | BH109: =+I109 -> #REF! | ... BN109: =+O109 -> #REF!
B110: =+#REF! -> #REF! | C110: =+#REF! -> #REF! | D110: =+#REF! -> #REF! | E110: =+#REF! -> #REF! | F110: =+#REF! -> #REF! | G110: =+#REF! -> #REF! | H110: =+#REF! -> #REF! | I110: =+#REF! -> #REF! | ... N110: =+#REF! -> #REF! | O110: =SUM(C110:N110) -> #REF! | P110: =+AVERAGE(C110:N110) -> #REF! | Q110: =+O110/$O$141 -> #REF! | BA110: =+B110 -> #REF! | BB110: =+C110 -> #REF! | BC110: =+D110 -> #REF! | BD110: =+E110 -> #REF! | BE110: =+F110 -> #REF! | BF110: =+G110 -> #REF! | BG110: =+H110 -> #REF! | BH110: =+I110 -> #REF! | ... BN110: =+O110 -> #REF!
...

Sheet SECCIÓN I
B1: SUPERINTENDENCIA DE BANCOS DEL ECUADOR INTENDENCIA NACIONAL DE RIESGOS Y ESTUDIOS DIRECCIÓN DE ESTUDIOS Y GESTIÓN DE LA INFORMACIÓN SUBDIRECCIÓN DE ESTADÍSTICAS Y ESTUDIOS
B3: ESTADÍSTICAS DE RETIROS DE DINERO EN EFECTIVO SOBRE CUENTAS DE AHORRO EN CANALES PROPIOS DE LA ENTIDAD
B4: Enero a Diciembre 2020
B5: Fecha de publicación: Enero 2021
B6: Datos Provisionales
B8: SECCIÓN I: RETIROS DE DINERO EN GENERAL
B10: 1.1 Evolución de Transacciones y Montos de Retiros de Dinero
C11: 3 | D11: 4 | E11: 5 | F11: 6 | G11: 7 | H11: 8 | I11: 9 | J11: 10 | K11: 11 | L11: 12 | M11: 13 | N11: 14 | O11: 15
B12: Tipo de Entidad | C12: Enero | D12: Febrero | E12: Marzo | F12: Abril | G12: Mayo | H12: Junio | I12: Julio | J12: Agosto | K12: Septiembre | L12: Octubre | M12: Noviembre | N12: Diciembre | O12: Total | P12: Promedio
B13: Número de Retiros | C13: 21544651 | D13: 20636370 | E13: 16135331 | F13: 9464804 | G13: 11658889 | H13: 14957371 | I13: 16297665 | J13: 16897460 | K13: 17528920 | L13: 19102888 | M13: 18152210 | N13: 23519450 | O13: 2.0589601e+08 | P13: 17158001
B14: Monto de Retiros | C14: 3.5410659e+09 | D14: 3.3005592e+09 | E14: 2.7782638e+09 | F14: 1.7651048e+09 | G14: 2.0501476e+09 | H14: 2.55783e+09 | I14: 2.7437331e+09 | J14: 2.7246167e+09 | K14: 2.9052076e+09 | L14: 3.0969903e+09 | M14: 2.8566374e+09 | N14: 3.8389795e+09 | O14: 3.4159136e+10 | P14: 2.8465947e+09
B15: Monto Promedio por Retiro | C15: 164.3594 | D15: 159.93894 | E15: 172.18511 | F15: 186.49142 | G15: 175.84416 | H15: 171.008 | I15: 168.3513 | J15: 161.24416 | K15: 165.73797 | L15: 162.12158 | M15: 157.37133 | N15: 163.22573 | P15: 165.9048

Sheet SECCIÓN II
B1: SUPERINTENDENCIA DE BANCOS DEL ECUADOR INTENDENCIA NACIONAL DE RIESGOS Y ESTUDIOS DIRECCIÓN DE ESTUDIOS Y GESTIÓN DE LA INFORMACIÓN SUBDIRECCIÓN DE ESTADÍSTICAS Y ESTUDIOS
B3: ESTADÍSTICAS DE RETIROS DE DINERO EN EFECTIVO SOBRE CUENTAS DE AHORRO EN CANALES PROPIOS DE LA ENTIDAD
B4: Enero a Diciembre 2020
B5: Fecha de publicación: Enero 2021
B6: Datos Provisionales
B8: SECCIÓN II: RETIROS DE DINERO POR ENTIDAD FINANCIERA
B10: 2.1 Evolución de Transacciones de Retiros de Dinero por Entidad Financiera
C11: 2 | D11: 3 | E11: 4 | F11: 5 | G11: 6 | H11: 7 | I11: 8 | J11: 9 | K11: 10 | L11: 11 | M11: 12 | N11: 13 | O11: 14 | P11: 15
B12: Entidad Financiera | C12: Enero | D12: Febrero | E12: Marzo | F12: Abril | G12: Mayo | H12: Junio | I12: Julio | J12: Agosto | K12: Septiembre | L12: Octubre | M12: Noviembre | N12: Diciembre | O12: Total | P12: Promedio | Q12: % Número de Retiros | BA12: Entidad Financiera | BB12: Enero | BC12: Febrero | BD12: Marzo | BE12: Abril | BF12: Mayo | BG12: Junio | BH12: Julio | BI12: Agosto | BJ12: Septiembre | BK12: Octubre | BL12: Noviembre | BM12: Diciembre | BN12: Total
B13: Banco Pichincha | C13: 9356898 | D13: 9143527 | E13: 6702892 | F13: 3747549 | G13: 4727072 | H13: 6321403 | I13: 7034388 | J13: 7368183 | K13: 7682739 | L13: 8612765 | M13: 8079432 | N13: 9903107 | O13: 88679955 | P13: 7389996.2 | Q13: 0.43070264 | BA13: Banco Pichincha | BB13: 9356898 | BC13: 9143527 | BD13: 6702892 | BE13: 3747549 | BF13: 4727072 | BG13: 6321403 | BH13: 7034388 | BI13: 7368183 | BJ13: 7682739 | BK13: 8612765 | BL13: 8079432 | BM13: 9903107 | BN13: 88679955
B14: Banco de Guayaquil | C14: 3636390 | D14: 3339408 | E14: 3012153 | F14: 1838633 | G14: 2109870 | H14: 2764666 | I14: 2923349 | J14: 3017675 | K14: 3090959 | L14: 3267287 | M14: 3338384 | N14: 3959865 | O14: 36298639 | P14: 3024886.6 | Q14: 0.17629598 | BA14: Banco de Guayaquil | BB14: 3636390 | BC14: 3339408 | BD14: 3012153 | BE14: 1838633 | BF14: 2109870 | BG14: 2764666 | BH14: 2923349 | BI14: 3017675 | BJ14: 3090959 | BK14: 3267287 | BL14: 3338384 | BM14: 3959865 | BN14: 36298639
B15: Banco del Pacífico | C15: 2913669 | D15: 2820005 | E15: 2194288 | F15: 1376443 | G15: 1745571 | H15: 2038885 | I15: 2198389 | J15: 2257560 | K15: 2373335 | L15: 2619315 | M15: 2403631 | N15: 3110757 | O15: 28051848 | P15: 2337654 | Q15: 0.1362428 | BA15: Banco del Pacífico | BB15: 2913669 | BC15: 2820005 | BD15: 2194288 | BE15: 1376443 | BF15: 1745571 | BG15: 2038885 | BH15: 2198389 | BI15: 2257560 | BJ15: 2373335 | BK15: 2619315 | BL15: 2403631 | BM15: 3110757 | BN15: 28051848
B16: Banco Bolivariano | C16: 1350730 | D16: 1214459 | E16: 1113232 | F16: 693058 | G16: 821626 | H16: 1052001 | I16: 1085012 | J16: 1080692 | K16: 1092927 | L16: 1139120 | M16: 1167595 | N16: 1404740 | O16: 13215192 | P16: 1101266 | Q16: 0.064183818 | BA16: Banco Bolivariano | BB16: 1350730 | BC16: 1214459 | BD16: 1113232 | BE16: 693058 | BF16: 821626 | BG16: 1052001 | BH16: 1085012 | BI16: 1080692 | BJ16: 1092927 | BK16: 1139120 | BL16: 1167595 | BM16: 1404740 | BN16: 13215192
B17: Banco Produbanco Grupo Promerica | C17: 1357634 | D17: 1318129 | E17: 967959 | F17: 535153 | G17: 659922 | H17: 857609 | I17: 931269 | J17: 979707 | K17: 988654 | L17: 1084712 | M17: 986301 | N17: 2411463 | O17: 13078512 | P17: 1089876 | Q17: 0.063519988 | BA17: Banco Produbanco Grupo Promerica | BB17: 1357634 | BC17: 1318129 | BD17: 967959 | BE17: 535153 | BF17: 659922 | BG17: 857609 | BH17: 931269 | BI17: 979707 | BJ17: 988654 | BK17: 1084712 | BL17: 986301 | BM17: 2411463 | BN17: 13078512
B18: Banco Internacional | C18: 902995 | D18: 876204 | E18: 674958 | F18: 458031 | G18: 542643 | H18: 557760 | I18: 655232 | J18: 692225 | K18: 697769 | L18: 760043 | M18: 692642 | N18: 836946 | O18: 8347448 | P18: 695620.67 | Q18: 0.040542058 | BA18: Banco Internacional | BB18: 902995 | BC18: 876204 | BD18: 674958 | BE18: 458031 | BF18: 542643 | BG18: 557760 | BH18: 655232 | BI18: 692225 | BJ18: 697769 | BK18: 760043 | BL18: 692642 | BM18: 836946 | BN18: 8347448
B19: Banco del Austro | C19: 556494 | D19: 526347 | E19: 393095 | F19: 225464 | G19: 296577 | H19: 381135 | I19: 411705 | J19: 426684 | K19: 447248 | L19: 480385 | M19: 445430 | N19: 552175 | O19: 5142739 | P19: 428561.58 | Q19: 0.024977361 | BA19: Resto de Entidades Financieras | BB19: 2026335 | BC19: 1924638 | BD19: 1469849 | BE19: 815937 | BF19: 1052185 | BG19: 1365047 | BH19: 1470026 | BI19: 1501418 | BJ19: 1602537 | BK19: 1619646 | BL19: 1484225 | BM19: 1892572 | BN19: 18224415
B20: Banco de Loja | C20: 427872 | D20: 417583 | E20: 304755 | F20: 160986 | G20: 212810 | H20: 278517 | I20: 298521 | J20: 311001 | K20: 339530 | L20: 269509 | M20: 248919 | N20: 318619 | O20: 3588622 | P20: 299051.83 | Q20: 0.017429294 | BA20: Banco del Austro | BB20: 556494 | BC20: 526347 | BD20: 393095 | BE20: 225464 | BF20: 296577 | BG20: 381135 | BH20: 411705 | BI20: 426684 | BJ20: 447248 | BK20: 480385 | BL20: 445430 | BM20: 552175 | BN20: 5142739
B21: Banco General Rumiñahui | C21: 289814 | D21: 275525 | E21: 218543 | F21: 148279 | G21: 182977 | H21: 200127 | I21: 213682 | J21: 231768 | K21: 249766 | L21: 268317 | M21: 226045 | N21: 327536 | O21: 2832379 | P21: 236031.58 | Q21: 0.013756357 | BA21: Banco de Loja | BB21: 427872 | BC21: 417583 | BD21: 304755 | BE21: 160986 | BF21: 212810 | BG21: 278517 | BH21: 298521 | BI21: 311001 | BJ21: 339530 | BK21: 269509 | BL21: 248919 | BM21: 318619 | BN21: 3588622
B22: Banco de Machala | C22: 299049 | D22: 276479 | E22: 245096 | F22: 141872 | G22: 168605 | H22: 216421 | I22: 230390 | J22: 221278 | K22: 234436 | L22: 248425 | M22: 237392 | N22: 298372 | O22: 2817815 | P22: 234817.92 | Q22: 0.013685622 | BA22: Banco General Rumiñahui | BB22: 289814 | BC22: 275525 | BD22: 218543 | BE22: 148279 | BF22: 182977 | BG22: 200127 | BH22: 213682 | BI22: 231768 | BJ22: 249766 | BK22: 268317 | BL22: 226045 | BM22: 327536 | BN22: 2832379
B23: Banco Coopnacional | C23: 108524 | D23: 96850 | E23: 80882 | F23: 48106 | G23: 64534 | H23: 88278 | I23: 92482 | J23: 81442 | K23: 88894 | L23: 92258 | M23: 85319 | N23: 96629 | O23: 1024198 | P23: 85349.833 | Q23: 0.0049743461 | BA23: Banco de Machala | BB23: 299049 | BC23: 276479 | BD23: 245096 | BE23: 141872 | BF23: 168605 | BG23: 216421 | BH23: 230390 | BI23: 221278 | BJ23: 234436 | BK23: 248425 | BL23: 237392 | BM23: 298372 | BN23: 2817815
B24: Servipagos | C24: 134279 | D24: 132045 | E24: 76573 | F24: 12642 | G24: 26315 | H24: 65330 | I24: 74841 | J24: 82202 | K24: 83161 | L24: 92640 | M24: 81381 | N24: 99360 | O24: 960769 | P24: 80064.083 | Q24: 0.0046662828 | BA24: Servipagos | BB24: 134279 | BC24: 132045 | BD24: 76573 | BE24: 12642 | BF24: 26315 | BG24: 65330 | BH24: 74841 | BI24: 82202 | BJ24: 83161 | BK24: 92640 | BL24: 81381 | BM24: 99360 | BN24: 960769
... B36: Total | C36: 21544651 | D36: 20636370 | E36: 16135331 | F36: 9464804 | G36: 11658889 | H36: 14957371 | I36: 16297665 | J36: 16897460 | K36: 17528920 | L36: 19102888 | M36: 18152210 | N36: 23519450 | O36: 205896009 | P36: 17158001 | Q36: 1 | BA36: Banco Visionfund | BB36: 8102 | BC36: 7451 | BD36: 4897 | BE36: 1560 | BF36: 1751 | BG36: 2425 | BH36: 5520 | BI36: 6735 | BJ36: 7394 | BK36: 7554 | BL36: 7423 | BM36: 8665 | BN36: 69477
BA37: Total | BB37: 21544651 | BC37: 20636370 | BD37: 16135331 | BE37: 9464804 | BF37: 11658889 | BG37: 14957371 | BH37: 16297665 | BI37: 16897460 | BJ37: 17528920 | BK37: 19102888 | BL37: 18152210 | BM37: 23519450 | BN37: 205896009
B63: 2.2 Evolución del Monto de Retiros de Dinero por Entidad Financiera
B64: (en dólares)
B65: Entidad Financiera | C65: Enero | D65: Febrero | E65: Marzo | F65: Abril | G65: Mayo | H65: Junio | I65: Julio | J65: Agosto | K65: Septiembre | L65: Octubre | M65: Noviembre | N65: Diciembre | O65: Total | P65: Promedio | Q65: % Monto por Retiros | BA65: Entidad Financiera | BB65: Enero | BC65: Febrero | BD65: Marzo | BE65: Abril | BF65: Mayo | BG65: Junio | BH65: Julio | BI65: Agosto | BJ65: Septiembre | BK65: Octubre | BL65: Noviembre | BM65: Diciembre | BN65: Total
B66: Banco Pichincha | C66: 1.6541333e+09 | D66: 1.5757648e+09 | E66: 1.2453934e+09 | F66: 7.3666686e+08 | G66: 8.9642399e+08 | H66: 1.1848766e+09 | I66: 1.2851275e+09 | J66: 1.2907008e+09 | K66: 1.3758687e+09 | L66: 1.5112006e+09 | M66: 1.383773e+09 | N66: 1.7547046e+09 | O66: 1.5894634e+10 | P66: 1.3245528e+09 | Q66: 0.46531137 | BA66: Banco Pichincha | BB66: 1.6541333e+09 | BC66: 1.5757648e+09 | BD66: 1.2453934e+09 | BE66: 7.3666686e+08 | BF66: 8.9642399e+08 | BG66: 1.1848766e+09 | BH66: 1.2851275e+09 | BI66: 1.2907008e+09 | BJ66: 1.3758687e+09 | BK66: 1.5112006e+09 | BL66: 1.383773e+09 | BM66: 1.7547046e+09 | BN66: 1.5894634e+10
B67: Banco de Guayaquil | C67: 4.0922588e+08 | D67: 3.5361336e+08 | E67: 3.4138197e+08 | F67: 2.2850172e+08 | G67: 2.5062819e+08 | H67: 2.9608052e+08 | I67: 3.1496587e+08 | J67: 3.0183259e+08 | K67: 3.2568453e+08 | L67: 3.4205769e+08 | M67: 3.4002513e+08 | N67: 4.4537263e+08 | O67: 3.9493701e+09 | P67: 3.2911417e+08 | Q67: 0.1156168 | BA67: Banco de Guayaquil | BB67: 4.0922588e+08 | BC67: 3.5361336e+08 | BD67: 3.4138197e+08 | BE67: 2.2850172e+08 | BF67: 2.5062819e+08 | BG67: 2.9608052e+08 | BH67: 3.1496587e+08 | BI67: 3.0183259e+08 | BJ67: 3.2568453e+08 | BK67: 3.4205769e+08 | BL67: 3.4002513e+08 | BM67: 4.4537263e+08 | BN67: 3.9493701e+09
B68: Banco del Pacífico | C68: 3.5582017e+08 | D68: 3.3227203e+08 | E68: 2.8995302e+08 | F68: 2.0238085e+08 | G68: 2.4222735e+08 | H68: 2.6760948e+08 | I68: 2.8088622e+08 | J68: 2.8086719e+08 | K68: 2.9492452e+08 | L68: 3.1797207e+08 | M68: 2.8449394e+08 | N68: 4.0532337e+08 | O68: 3.5547302e+09 | P68: 2.9622752e+08 | Q68: 0.10406382 | BA68: Banco del Pacífico | BB68: 3.5582017e+08 | BC68: 3.3227203e+08 | BD68: 2.8995302e+08 | BE68: 2.0238085e+08 | BF68: 2.4222735e+08 | BG68: 2.6760948e+08 | BH68: 2.8088622e+08 | BI68: 2.8086719e+08 | BJ68: 2.9492452e+08 | BK68: 3.1797207e+08 | BL68: 2.8449394e+08 | BM68: 4.0532337e+08 | BN68: 3.5547302e+09
B69: Banco Produbanco Grupo Promerica | C69: 2.5399982e+08 | D69: 2.4066916e+08 | E69: 1.9539707e+08 | F69: 1.4325534e+08 | G69: 1.5257241e+08 | H69: 1.7374205e+08 | I69: 1.8044785e+08 | J69: 1.8586157e+08 | K69: 1.9110929e+08 | L69: 2.0539563e+08 | M69: 1.8224619e+08 | N69: 4.0109357e+08 | O69: 2.50579e+09 | P69: 2.0881583e+08 | Q69: 0.073356363 | BA69: Banco Bolivariano | BB69: 2.2521223e+08 | BC69: 2.0246167e+08 | BD69: 2.0692242e+08 | BE69: 1.5289974e+08 | BF69: 1.5533901e+08 | BG69: 1.8893491e+08 | BH69: 1.924674e+08 | BI69: 1.8452875e+08 | BJ69: 1.920817e+08 | BK69: 2.0288985e+08 | BL69: 2.0193008e+08 | BM69: 2.6494707e+08 | BN69: 2.3706148e+09
B70: Banco Bolivariano | C70: 2.2521223e+08 | D70: 2.0246167e+08 | E70: 2.0692242e+08 | F70: 1.5289974e+08 | G70: 1.5533901e+08 | H70: 1.8893491e+08 | I70: 1.924674e+08 | J70: 1.8452875e+08 | K70: 1.920817e+08 | L70: 2.0288985e+08 | M70: 2.0193008e+08 | N70: 2.6494707e+08 | O70: 2.3706148e+09 | P70: 1.9755123e+08 | Q70: 0.069399145 | BA70: Banco Produbanco Grupo Promerica | BB70: 2.5399982e+08 | BC70: 2.4066916e+08 | BD70: 1.9539707e+08 | BE70: 1.4325534e+08 | BF70: 1.5257241e+08 | BG70: 1.7374205e+08 | BH70: 1.8044785e+08 | BI70: 1.8586157e+08 | BJ70: 1.9110929e+08 | BK70: 2.0539563e+08 | BL70: 1.8224619e+08 | BM70: 4.0109357e+08 | BN70: 2.50579e+09
B71: Banco Internacional | C71: 1.4210931e+08 | D71: 1.321181e+08 | E71: 1.1333408e+08 | F71: 86138783 | G71: 95877276 | H71: 1.0252598e+08 | I71: 1.1360103e+08 | J71: 1.1411239e+08 | K71: 1.1632523e+08 | L71: 1.2753117e+08 | M71: 1.1406114e+08 | N71: 89137800 | O71: 1.3468723e+09 | P71: 1.1223936e+08 | Q71: 0.039429343 | BA71: Resto de Entidades Financieras | BB71: 6.4267449e+08 | BC71: 5.9577816e+08 | BD71: 4.992159e+08 | BE71: 3.0140025e+08 | BF71: 3.5295662e+08 | BG71: 4.4658649e+08 | BH71: 4.8983825e+08 | BI71: 4.8082575e+08 | BJ71: 5.255389e+08 | BK71: 5.1747444e+08 | BL71: 4.641691e+08 | BM71: 5.6753827e+08 | BN71: 5.8839966e+09
B72: Banco del Austro | C72: 1.365322e+08 | D72: 1.2357656e+08 | E72: 1.0474295e+08 | F72: 58531340 | G72: 71587434 | H72: 95844230 | I72: 1.0525887e+08 | J72: 1.0717132e+08 | K72: 1.1611619e+08 | L72: 1.1755051e+08 | M72: 1.0627087e+08 | N72: 1.3691934e+08 | O72: 1.2801018e+09 | P72: 1.0667515e+08 | Q72: 0.037474654 | BA72: Banco Internacional | BB72: 1.4210931e+08 | BC72: 1.321181e+08 | BD72: 1.1333408e+08 | BE72: 86138783 | BF72: 95877276 | BG72: 1.0252598e+08 | BH72: 1.1360103e+08 | BI72: 1.1411239e+08 | BJ72: 1.1632523e+08 | BK72: 1.2753117e+08 | BL72: 1.1406114e+08 | BM72: 89137800 | BN72: 1.3468723e+09
B73: Banco de Machala | C73: 79569822 | D73: 70779163 | E73: 68669727 | F73: 45206929 | G73: 49345990 | H73: 60807114 | I73: 65623766 | J73: 58221386 | K73: 64905460 | L73: 68646878 | M73: 62546436 | N73: 88197164 | O73: 7.8251984e+08 | P73: 65209986 | Q73: 0.022908069 | BA73: Banco del Austro | BB73: 1.365322e+08 | BC73: 1.2357656e+08 | BD73: 1.0474295e+08 | BE73: 58531340 | BF73: 71587434 | BG73: 95844230 | BH73: 1.0525887e+08 | BI73: 1.0717132e+08 | BJ73: 1.1611619e+08 | BK73: 1.1755051e+08 | BL73: 1.0627087e+08 | BM73: 1.3691934e+08 | BN73: 1.2801018e+09
B74: Banco General Rumiñahui | C74: 73711385 | D74: 69071221 | E74: 58154928 | F74: 38451208 | G74: 41930819 | H74: 48372496 | I74: 51623555 | J74: 54432164 | K74: 62885338 | L74: 66839701 | M74: 54216950 | N74: 88125615 | O74: 7.0781538e+08 | P74: 58984615 | Q74: 0.020721115 | BA74: Banco de Machala | BB74: 79569822 | BC74: 70779163 | BD74: 68669727 | BE74: 45206929 | BF74: 49345990 | BG74: 60807114 | BH74: 65623766 | BI74: 58221386 | BJ74: 64905460 | BK74: 68646878 | BL74: 62546436 | BM74: 88197164 | BN74: 7.8251984e+08
B75: Banco de Loja | C75: 67294450 | D75: 64666850 | E75: 52151334 | F75: 29755413 | G75: 34290650 | H75: 44226758 | I75: 49796384 | J75: 50454277 | K75: 56273643 | L75: 23234510 | M75: 20715290 | N75: 29089900 | O75: 5.2194946e+08 | P75: 43495788 | Q75: 0.015279937 | BA75: Banco General Rumiñahui | BB75: 73711385 | BC75: 69071221 | BD75: 58154928 | BE75: 38451208 | BF75: 41930819 | BG75: 48372496 | BH75: 51623555 | BI75: 54432164 | BJ75: 62885338 | BK75: 66839701 | BL75: 54216950 | BM75: 88125615 | BN75: 7.0781538e+08
B76: Banco Coopnacional | C76: 29766216 | D76: 26774148 | E76: 26636184 | F76: 16189595 | G76: 22133240 | H76: 31118898 | I76: 30616668 | J76: 22703824 | K76: 26949334 | L76: 28176294 | M76: 25052074 | N76: 33821876 | O76: 319938351 | P76: 26661529 | Q76: 0.0093661137 | BA76: Banco de Loja | BB76: 67294450 | BC76: 64666850 | BD76: 52151334 | BE76: 29755413 | BF76: 34290650 | BG76: 44226758 | BH76: 49796384 | BI76: 50454277 | BJ76: 56273643 | BK76: 23234510 | BL76: 20715290 | BM76: 29089900 | BN76: 5.2194946e+08
B77: Servipagos | C77: 37277424 | D77: 35709370 | E77: 22985299 | F77: 5615120.1 | G77: 9743524.9 | H77: 24154218 | I77: 26205201 | J77: 25966200 | K77: 25383993 | L77: 27444599 | M77: 23735788 | N77: 32152700 | O77: 2.9637344e+08 | P77: 24697786 | Q77: 0.0086762569 | BA77: Servipagos | BB77: 37277424 | BC77: 35709370 | BD77: 22985299 | BE77: 5615120.1 | BF77: 9743524.9 | BG77: 24154218 | BH77: 26205201 | BI77: 25966200 | BJ77: 25383993 | BK77: 27444599 | BL77: 23735788 | BM77: 32152700 | BN77: 2.9637344e+08
... B89: Total | C89: 3.5410659e+09 | D89: 3.3005592e+09 | E89: 2.7782638e+09 | F89: 1.7651048e+09 | G89: 2.0501476e+09 | H89: 2.55783e+09 | I89: 2.7437331e+09 | J89: 2.7246167e+09 | K89: 2.9052076e+09 | L89: 3.0969903e+09 | M89: 2.8566374e+09 | N89: 3.8389795e+09 | O89: 3.4159136e+10 | P89: 2.8465947e+09 | Q89: 1 | BA89: Banco Visionfund | BB89: 6030139.3 | BC89: 5648501 | BD89: 3198082.7 | BE89: 507589.24 | BF89: 452717.21 | BG89: 874689.67 | BH89: 4024229.8 | BI89: 5068524.1 | BJ89: 5730839.5 | BK89: 5756937.1 | BL89: 6010455.9 | BM89: 6719545.9 | BN89: 50022251
BA90: Total | BB90: 3.5410659e+09 | BC90: 3.3005592e+09 | BD90: 2.7782638e+09 | BE90: 1.7651048e+09 | BF90: 2.0501476e+09 | BG90: 2.55783e+09 | BH90: 2.7437331e+09 | BI90: 2.7246167e+09 | BJ90: 2.9052076e+09 | BK90: 3.0969903e+09 | BL90: 2.8566374e+09 | BM90: 3.8389795e+09 | BN90: 3.4159136e+10
...

Sheet SECCIÓN III
B1: SUPERINTENDENCIA DE BANCOS DEL ECUADOR INTENDENCIA NACIONAL DE RIESGOS Y ESTUDIOS DIRECCIÓN DE ESTUDIOS Y GESTIÓN DE LA INFORMACIÓN SUBDIRECCIÓN DE ESTADÍSTICAS Y ESTUDIOS
B3: ESTADÍSTICAS DE RETIROS DE DINERO EN EFECTIVO SOBRE CUENTAS DE AHORRO EN CANALES PROPIOS DE LA ENTIDAD
B4: Enero a Diciembre 2020
B5: Fecha de publicación: Enero 2021
B6: Datos Provisionales
B8: SECCIÓN III: RETIROS DE DINERO POR CANALES
B10: 3.1 Evolución de Transacciones de Retiros de Dinero por Canales
C11: 2 | D11: 3 | E11: 4 | F11: 5 | G11: 6 | H11: 7 | I11: 8 | J11: 9 | K11: 10 | L11: 11 | M11: 12 | N11: 13 | O11: 14 | P11: 15
B12: Canal | C12: Enero | D12: Febrero | E12: Marzo | F12: Abril | G12: Mayo | H12: Junio | I12: Julio | J12: Agosto | K12: Septiembre | L12: Octubre | M12: Noviembre | N12: Diciembre | O12: Total | P12: Promedio | Q12: % Número de Retiros
B13: Cajero Automático | C13: 15002936 | D13: 14474861 | E13: 11357557 | F13: 6585609 | G13: 8051740 | H13: 10170243 | I13: 11045419 | J13: 11519404 | K13: 11808526 | L13: 13009865 | M13: 12402841 | N13: 16622226 | O13: 1.4205123e+08 | P13: 11837602 | Q13: 0.68991734
B14: Cajero Automático Plus | C14: 1061580 | D14: 1030535 | E14: 823295 | F14: 563150 | G14: 718275 | H14: 811461 | I14: 883216 | J14: 937020 | K14: 1002649 | L14: 1126218 | M14: 1059601 | N14: 1390965 | O14: 11407965 | P14: 950663.75 | Q14: 0.055406441
B15: Cajero Automático Móvil | C15: 0 | D15: 0 | E15: 0 | F15: 0 | G15: 0 | H15: 0 | I15: 0 | J15: 0 | K15: 0 | L15: 0 | M15: 0 | N15: 0 | O15: 0 | P15: 0 | Q15: 0
B16: Corresponsal No Bancario | C16: 2421834 | D16: 2375742 | E16: 1844106 | F16: 1280021 | G16: 1589520 | H16: 2040228 | I16: 2275250 | J16: 2402410 | K16: 2496329 | L16: 2739326 | M16: 2628632 | N16: 3110279 | O16: 27203677 | P16: 2266973.1 | Q16: 0.13212338
B17: Oficina / Ventanilla | C17: 3025718 | D17: 2724380 | E17: 2086873 | F17: 1022373 | G17: 1285090 | H17: 1916952 | I17: 2075548 | J17: 2019533 | K17: 2202033 | L17: 2207342 | M17: 2043685 | N17: 2371113 | O17: 24980640 | P17: 2081720 | Q17: 0.12132649
B18: Ventanilla Compartida | C18: 32583 | D18: 30852 | E18: 23500 | F18: 13651 | G18: 14264 | H18: 18487 | I18: 18232 | J18: 19093 | K18: 19383 | L18: 20137 | M18: 17451 | N18: 24867 | O18: 252500 | P18: 21041.667 | Q18: 0.0012263472
B19: Total | C19: 21544651 | D19: 20636370 | E19: 16135331 | F19: 9464804 | G19: 11658889 | H19: 14957371 | I19: 16297665 | J19: 16897460 | K19: 17528920 | L19: 19102888 | M19: 18152210 | N19: 23519450 | O19: 2.0589601e+08 | P19: 17158001 | Q19: 1
B46: 3.2 Evolución del Monto de Retiros de Dinero por Canales
B47: (en dólares)
B48: Canal | C48: Enero | D48: Febrero | E48: Marzo | F48: Abril | G48: Mayo | H48: Junio | I48: Julio | J48: Agosto | K48: Septiembre | L48: Octubre | M48: Noviembre | N48: Diciembre | O48: Total | P48: Promedio | Q48: % Monto por Retiros
B49: Cajero Automático | C49: 1.4534694e+09 | D49: 1.4261195e+09 | E49: 1.2377401e+09 | F49: 842212955 | G49: 9.8786582e+08 | H49: 1.1226309e+09 | I49: 1.2018758e+09 | J49: 1.2467402e+09 | K49: 1.2555665e+09 | L49: 1.3760303e+09 | M49: 1.2819948e+09 | N49: 1.9249981e+09 | O49: 1.5357244e+10 | P49: 1.2797704e+09 | Q49: 0.44957941
B50: Cajero Automático Plus | C50: 95000696 | D50: 94021679 | E50: 83379548 | F50: 66082994 | G50: 80328002 | H50: 83171203 | I50: 88145573 | J50: 92139606 | K50: 98064237 | L50: 1.1069605e+08 | M50: 1.0119057e+08 | N50: 1.502027e+08 | O50: 1.1424229e+09 | P50: 95201904 | Q50: 0.033444138
B51: Cajero Automático Móvil | C51: 0 | D51: 0 | E51: 0 | F51: 0 | G51: 0 | H51: 0 | I51: 0 | J51: 0 | K51: 0 | L51: 0 | M51: 0 | N51: 0 | O51: 0 | P51: 0 | Q51: 0
B52: Corresponsal No Bancario | C52: 1.5992788e+08 | D52: 1.5999948e+08 | E52: 1.3218417e+08 | F52: 99828259 | G52: 1.299024e+08 | H52: 1.5647305e+08 | I52: 1.7358102e+08 | J52: 1.8170907e+08 | K52: 1.8711822e+08 | L52: 2.0620502e+08 | M52: 1.9293653e+08 | N52: 2.5373734e+08 | O52: 2.0336024e+09 | P52: 1.6946687e+08 | Q52: 0.059533193
B53: Oficina / Ventanilla | C53: 1.8137305e+09 | D53: 1.6017557e+09 | E53: 1.3107494e+09 | F53: 7.4850412e+08 | G53: 8.4366399e+08 | H53: 1.1853988e+09 | I53: 1.2698526e+09 | J53: 1.1938063e+09 | K53: 1.3529683e+09 | L53: 1.3925326e+09 | M53: 1.2706155e+09 | N53: 1.4945447e+09 | O53: 1.5478123e+10 | P53: 1.2898436e+09 | Q53: 0.4531181
B54: Ventanilla Compartida | C54: 18937416 | D54: 18662824 | E54: 14210551 | F54: 8476438.3 | G54: 8387358.9 | H54: 10156050 | I54: 10278070 | J54: 10221517 | K54: 11490424 | L54: 11526369 | M54: 9899970.6 | N54: 15496688 | O54: 1.4774368e+08 | P54: 12311973 | Q54: 0.0043251585
B55: Total | C55: 3.5410659e+09 | D55: 3.3005592e+09 | E55: 2.7782638e+09 | F55: 1.7651048e+09 | G55: 2.0501476e+09 | H55: 2.55783e+09 | I55: 2.7437331e+09 | J55: 2.7246167e+09 | K55: 2.9052076e+09 | L55: 3.0969903e+09 | M55: 2.8566374e+09 | N55: 3.8389795e+09 | O55: 3.4159136e+10 | P55: 2.8465947e+09 | Q55: 1
B83: 3.3 Evolución del Monto Promedio de Retiros de Dinero por Canales
B84: (en dólares)
B85: Canal | C85: Enero | D85: Febrero | E85: Marzo | F85: Abril | G85: Mayo | H85: Junio | I85: Julio | J85: Agosto | K85: Septiembre | L85: Octubre | M85: Noviembre | N85: Diciembre | O85: Promedio
B86: Cajero Automático | C86: 96.879 | D86: 98.523882 | E86: 108.97943 | F86: 127.88688 | G86: 122.68973 | H86: 110.38388 | I86: 108.81215 | J86: 108.22957 | K86: 106.32711 | L86: 105.76822 | M86: 103.36299 | N86: 115.80868 | O86: 108.11061
B87: Cajero Automático Plus | C87: 89.489907 | D87: 91.235794 | E87: 101.27542 | F87: 117.34528 | G87: 111.83461 | H87: 102.49563 | I87: 99.800698 | J87: 98.332592 | K87: 97.805151 | L87: 98.29007 | M87: 95.498752 | N87: 107.98453 | O87: 100.14256
B88: Cajero Automático Móvil
B89: Corresponsal No Bancario | C89: 66.035854 | D89: 67.347159 | E89: 71.67927 | F89: 77.989548 | G89: 81.724293 | H89: 76.693903 | I89: 76.290965 | J89: 75.636163 | K89: 74.957354 | L89: 75.275823 | M89: 73.398077 | N89: 81.580252 | O89: 74.75469
B90: Oficina / Ventanilla | C90: 599.43805 | D90: 587.93403 | E90: 628.09257 | F90: 732.1243 | G90: 656.50187 | H90: 618.3769 | I90: 611.81558 | J90: 591.12989 | K90: 614.41782 | L90: 630.86401 | M90: 621.72769 | N90: 630.31357 | O90: 619.60473
B91: Ventanilla Compartida | C91: 581.20541 | D91: 604.91455 | E91: 604.70431 | F91: 620.939 | G91: 588.0089 | H91: 549.36169 | I91: 563.73796 | J91: 535.35417 | K91: 592.80936 | L91: 572.39753 | M91: 567.30105 | N91: 623.18287 | O91: 585.12347
B92: Promedio | C92: 164.3594 | D92: 159.93894 | E92: 172.18511 | F92: 186.49142 | G92: 175.84416 | H92: 171.008 | I92: 168.3513 | J92: 161.24416 | K92: 165.73797 | L92: 162.12158 | M92: 157.37133 | N92: 163.22573 | O92: 165.9048
B119: 3.4 Resumen Anual de Transacciones, Monto de Retiros y Monto Promedio de Retiros de Dinero por Canales
B121: Canal | C121: Transacciones | D121: Monto de Retiros (USD) | E121: Monto promedio de Retiros (USD) | F121: % Transacciones | G121: % Monto de Retiros
B122: Cajero Automático | C122: 1.4205123e+08 | D122: 1.5357244e+10 | E122: 108.11061 | F122: 0.68991734 | G122: 0.44957941
B123: Cajero Automático Plus | C123: 11407965 | D123: 1.1424229e+09 | E123: 100.14256 | F123: 0.055406441 | G123: 0.033444138
...

Sheet SECCIÓN IV
B1: SUPERINTENDENCIA DE BANCOS DEL ECUADOR INTENDENCIA NACIONAL DE RIESGOS Y ESTUDIOS DIRECCIÓN DE ESTUDIOS Y GESTIÓN DE LA INFORMACIÓN SUBDIRECCIÓN DE ESTADÍSTICAS Y ESTUDIOS
B3: ESTADÍSTICAS DE RETIROS DE DINERO EN EFECTIVO SOBRE CUENTAS DE AHORRO EN CANALES PROPIOS DE LA ENTIDAD
B4: Enero a Diciembre 2020
B5: Fecha de publicación: Enero 2021
B6: Datos Provisionales
B8: SECCIÓN IV: RETIROS DE DINERO POR PROVINCIA
B10: 4.1 Evolución de Transacciones de Retiros de Dinero por Provincia
C11: 2 | D11: 3 | E11: 4 | F11: 5 | G11: 6 | H11: 7 | I11: 8 | J11: 9 | K11: 10 | L11: 11 | M11: 12 | N11: 13 | O11: 14 | P11: 15
B12: Provincia | C12: Enero | D12: Febrero | E12: Marzo | F12: Abril | G12: Mayo | H12: Junio | I12: Julio | J12: Agosto | K12: Septiembre | L12: Octubre | M12: Noviembre | N12: Diciembre | O12: Total | P12: Promedio | Q12: % Número de Retiros | BA12: Provincia | BB12: Enero | BC12: Febrero | BD12: Marzo | BE12: Abril | BF12: Mayo | BG12: Junio | BH12: Julio | BI12: Agosto | BJ12: Septiembre | BK12: Octubre | BL12: Noviembre | BM12: Diciembre | BN12: Total
B13: Guayas | C13: 6058163 | D13: 5662502 | E13: 4848238 | F13: 2957486 | G13: 3729841 | H13: 4735956 | I13: 4758919 | J13: 5073829 | K13: 4867620 | L13: 5655796 | M13: 5436233 | N13: 7023698 | O13: 60808281 | P13: 5067356.7 | Q13: 0.29533492 | BA13: Pichincha | BB13: 6732235 | BC13: 6434319 | BD13: 4661672 | BE13: 2551993 | BF13: 3052886 | BG13: 4122566 | BH13: 4517047 | BI13: 4907754 | BJ13: 5063423 | BK13: 5537827 | BL13: 5273107 | BM13: 7006925 | BN13: 59861754
B14: Pichincha | C14: 6732235 | D14: 6434319 | E14: 4661672 | F14: 2551993 | G14: 3052886 | H14: 4122566 | I14: 4517047 | J14: 4907754 | K14: 5063423 | L14: 5537827 | M14: 5273107 | N14: 7006925 | O14: 59861754 | P14: 4988479.5 | Q14: 0.29073781 | BA14: Guayas | BB14: 6058163 | BC14: 5662502 | BD14: 4848238 | BE14: 2957486 | BF14: 3729841 | BG14: 4735956 | BH14: 4758919 | BI14: 5073829 | BJ14: 4867620 | BK14: 5655796 | BL14: 5436233 | BM14: 7023698 | BN14: 60808281
B15: Manabí | C15: 1342389 | D15: 1316127 | E15: 1066040 | F15: 649353 | G15: 766840 | H15: 932156 | I15: 1050660 | J15: 1069112 | K15: 1119359 | L15: 1271446 | M15: 1170223 | N15: 1513608 | O15: 13267313 | P15: 1105609.4 | Q15: 0.064436961 | BA15: Manabí | BB15: 1342389 | BC15: 1316127 | BD15: 1066040 | BE15: 649353 | BF15: 766840 | BG15: 932156 | BH15: 1050660 | BI15: 1069112 | BJ15: 1119359 | BK15: 1271446 | BL15: 1170223 | BM15: 1513608 | BN15: 13267313
B16: Los Ríos | C16: 875193 | D16: 847885 | E16: 748356 | F16: 500919 | G16: 602591 | H16: 709896 | I16: 755673 | J16: 761873 | K16: 772070 | L16: 862832 | M16: 816487 | N16: 1049298 | O16: 9303073 | P16: 775256.08 | Q16: 0.045183358 | BA16: Los Ríos | BB16: 875193 | BC16: 847885 | BD16: 748356 | BE16: 500919 | BF16: 602591 | BG16: 709896 | BH16: 755673 | BI16: 761873 | BJ16: 772070 | BK16: 862832 | BL16: 816487 | BM16: 1049298 | BN16: 9303073
B17: Santo Domingo de los Tsáchilas | C17: 719587 | D17: 708088 | E17: 548445 | F17: 317816 | G17: 412404 | H17: 535366 | I17: 575893 | J17: 594287 | K17: 621432 | L17: 699115 | M17: 719455 | N17: 820175 | O17: 7272063 | P17: 606005.25 | Q17: 0.035319106 | BA17: Azuay | BB17: 690165 | BC17: 645366 | BD17: 465133 | BE17: 257995 | BF17: 337683 | BG17: 442041 | BH17: 889205 | BI17: 505276 | BJ17: 945978 | BK17: 567679 | BL17: 539657 | BM17: 686016 | BN17: 6972194
B18: Azuay | C18: 690165 | D18: 645366 | E18: 465133 | F18: 257995 | G18: 337683 | H18: 442041 | I18: 889205 | J18: 505276 | K18: 945978 | L18: 567679 | M18: 539657 | N18: 686016 | O18: 6972194 | P18: 581016.17 | Q18: 0.033862696 | BA18: Resto de Provincias | BB18: 5846506 | BC18: 5730171 | BD18: 4345892 | BE18: 2547058 | BF18: 3169048 | BG18: 4014756 | BH18: 4326161 | BI18: 4579616 | BJ18: 4760470 | BK18: 5207308 | BL18: 4916503 | BM18: 6239905 | BN18: 55683394
B19: El Oro | C19: 647936 | D19: 626072 | E19: 517041 | F19: 297970 | G19: 374257 | H19: 474121 | I19: 506170 | J19: 519297 | K19: 538446 | L19: 595078 | M19: 572484 | N19: 709357 | O19: 6378229 | P19: 531519.08 | Q19: 0.030977915 | BA19: El Oro | BB19: 647936 | BC19: 626072 | BD19: 517041 | BE19: 297970 | BF19: 374257 | BG19: 474121 | BH19: 506170 | BI19: 519297 | BJ19: 538446 | BK19: 595078 | BL19: 572484 | BM19: 709357 | BN19: 6378229
B20: Tungurahua | C20: 617685 | D20: 601224 | E20: 423257 | F20: 226715 | G20: 297430 | H20: 391537 | I20: 409535 | J20: 454946 | K20: 468454 | L20: 518029 | M20: 497733 | N20: 664379 | O20: 5570924 | P20: 464243.67 | Q20: 0.027056979 | BA20: Santo Domingo de los Tsáchilas | BB20: 719587 | BC20: 708088 | BD20: 548445 | BE20: 317816 | BF20: 412404 | BG20: 535366 | BH20: 575893 | BI20: 594287 | BJ20: 621432 | BK20: 699115 | BL20: 719455 | BM20: 820175 | BN20: 7272063
B21: Esmeraldas | C21: 493574 | D21: 507635 | E21: 419237 | F21: 286848 | G21: 329521 | H21: 378501 | I21: 410200 | J21: 420072 | K21: 436884 | L21: 507628 | M21: 410855 | N21: 619067 | O21: 5220022 | P21: 435001.83 | Q21: 0.025352711 | BA21: Tungurahua | BB21: 617685 | BC21: 601224 | BD21: 423257 | BE21: 226715 | BF21: 297430 | BG21: 391537 | BH21: 409535 | BI21: 454946 | BJ21: 468454 | BK21: 518029 | BL21: 497733 | BM21: 664379 | BN21: 5570924
B22: Imbabura | C22: 506634 | D22: 501899 | E22: 358695 | F22: 196471 | G22: 242730 | H22: 326442 | I22: 365851 | J22: 397664 | K22: 405608 | L22: 444642 | M22: 422604 | N22: 539464 | O22: 4708704 | P22: 392392 | Q22: 0.022869331 | BA22: Imbabura | BB22: 506634 | BC22: 501899 | BD22: 358695 | BE22: 196471 | BF22: 242730 | BG22: 326442 | BH22: 365851 | BI22: 397664 | BJ22: 405608 | BK22: 444642 | BL22: 422604 | BM22: 539464 | BN22: 4708704
B23: Loja | C23: 533341 | D23: 511170 | E23: 371037 | F23: 189783 | G23: 256979 | H23: 347149 | I23: 368559 | J23: 386613 | K23: 422650 | L23: 377664 | M23: 350771 | N23: 447245 | O23: 4562961 | P23: 380246.75 | Q23: 0.022161483 | BA23: Esmeraldas | BB23: 493574 | BC23: 507635 | BD23: 419237 | BE23: 286848 | BF23: 329521 | BG23: 378501 | BH23: 410200 | BI23: 420072 | BJ23: 436884 | BK23: 507628 | BL23: 410855 | BM23: 619067 | BN23: 5220022
B24: Chimborazo | C24: 419703 | D24: 405565 | E24: 269510 | F24: 151495 | G24: 194076 | H24: 257125 | I24: 258374 | J24: 292842 | K24: 282493 | L24: 330150 | M24: 312285 | N24: 393244 | O24: 3566862 | P24: 297238.5 | Q24: 0.017323609 | BA24: Loja | BB24: 533341 | BC24: 511170 | BD24: 371037 | BE24: 189783 | BF24: 256979 | BG24: 347149 | BH24: 368559 | BI24: 386613 | BJ24: 422650 | BK24: 377664 | BL24: 350771 | BM24: 447245 | BN24: 4562961
... B37: Total | C37: 21544651 | D37: 20636370 | E37: 16135331 | F37: 9464804 | G37: 11658889 | H37: 14957371 | I37: 16297665 | J37: 16897460 | K37: 17528920 | L37: 19102888 | M37: 18152210 | N37: 23519450 | O37: 205896009 | P37: 17158001 | Q37: 1 | BA37: Morona Santiago | BB37: 41796 | BC37: 40616 | BD37: 29784 | BE37: 17870 | BF37: 23395 | BG37: 28185 | BH37: 29980 | BI37: 33778 | BJ37: 33399 | BK37: 33046 | BL37: 31489 | BM37: 38224 | BN37: 381562
BA38: Total | BB38: 21544651 | BC38: 20636370 | BD38: 16135331 | BE38: 9464804 | BF38: 11658889 | BG38: 14957371 | BH38: 16297665 | BI38: 16897460 | BJ38: 17528920 | BK38: 19102888 | BL38: 18152210 | BM38: 23519450 | BN38: 205896009
B65: 4.2 Evolución del Monto de Retiros de Dinero por Provincia
B66: (en dólares)
B67: Provincia | C67: Enero | D67: Febrero | E67: Marzo | F67: Abril | G67: Mayo | H67: Junio | I67: Julio | J67: Agosto | K67: Septiembre | L67: Octubre | M67: Noviembre | N67: Diciembre | O67: Total | P67: Promedio | Q67: % Monto por Retiros | BA67: Provincia | BB67: Enero | BC67: Febrero | BD67: Marzo | BE67: Abril | BF67: Mayo | BG67: Junio | BH67: Julio | BI67: Agosto | BJ67: Septiembre | BK67: Octubre | BL67: Noviembre | BM67: Diciembre | BN67: Total
B68: Guayas | C68: 9.2307799e+08 | D68: 8.5208458e+08 | E68: 7.8346478e+08 | F68: 5.2255139e+08 | G68: 6.2279071e+08 | H68: 7.4457042e+08 | I68: 7.6205326e+08 | J68: 7.3648963e+08 | K68: 7.6949081e+08 | L68: 8.5350102e+08 | M68: 7.9747791e+08 | N68: 1.0985997e+09 | O68: 9.4661522e+09 | P68: 7.8884602e+08 | Q68: 0.27711919 | BA68: Pichincha | BB68: 9.605419e+08 | BC68: 8.9905296e+08 | BD68: 7.0442296e+08 | BE68: 4.4008663e+08 | BF68: 4.8130572e+08 | BG68: 6.1225094e+08 | BH68: 6.5258259e+08 | BI68: 6.9333189e+08 | BJ68: 7.1881336e+08 | BK68: 7.6905379e+08 | BL68: 7.1206307e+08 | BM68: 9.8057847e+08 | BN68: 8.6240843e+09
B69: Pichincha | C69: 9.605419e+08 | D69: 8.9905296e+08 | E69: 7.0442296e+08 | F69: 4.4008663e+08 | G69: 4.8130572e+08 | H69: 6.1225094e+08 | I69: 6.5258259e+08 | J69: 6.9333189e+08 | K69: 7.1881336e+08 | L69: 7.6905379e+08 | M69: 7.1206307e+08 | N69: 9.8057847e+08 | O69: 8.6240843e+09 | P69: 7.1867369e+08 | Q69: 0.25246787 | BA69: Guayas | BB69: 9.2307799e+08 | BC69: 8.5208458e+08 | BD69: 7.8346478e+08 | BE69: 5.2255139e+08 | BF69: 6.2279071e+08 | BG69: 7.4457042e+08 | BH69: 7.6205326e+08 | BI69: 7.3648963e+08 | BJ69: 7.6949081e+08 | BK69: 8.5350102e+08 | BL69: 7.9747791e+08 | BM69: 1.0985997e+09 | BN69: 9.4661522e+09
B70: Manabí | C70: 2.2941528e+08 | D70: 2.1726446e+08 | E70: 1.8735575e+08 | F70: 1.1791145e+08 | G70: 1.39704e+08 | H70: 1.7268998e+08 | I70: 1.917471e+08 | J70: 1.8314506e+08 | K70: 1.9564428e+08 | L70: 2.1724303e+08 | M70: 1.9391673e+08 | N70: 2.6377827e+08 | O70: 2.3098154e+09 | P70: 1.9248462e+08 | Q70: 0.067619257 | BA70: Manabí | BB70: 2.2941528e+08 | BC70: 2.1726446e+08 | BD70: 1.8735575e+08 | BE70: 1.1791145e+08 | BF70: 1.39704e+08 | BG70: 1.7268998e+08 | BH70: 1.917471e+08 | BI70: 1.8314506e+08 | BJ70: 1.9564428e+08 | BK70: 2.1724303e+08 | BL70: 1.9391673e+08 | BM70: 2.6377827e+08 | BN70: 2.3098154e+09
B71: Azuay | C71: 1.6880606e+08 | D71: 1.5787865e+08 | E71: 1.1995637e+08 | F71: 74015293 | G71: 84732247 | H71: 1.133051e+08 | I71: 1.5075109e+08 | J71: 1.2817287e+08 | K71: 1.5944355e+08 | L71: 1.4126145e+08 | M71: 1.30207e+08 | N71: 1.6204825e+08 | O71: 1.5905779e+09 | P71: 1.3254816e+08 | Q71: 0.046563763 | BA71: Los Ríos | BB71: 1.4524556e+08 | BC71: 1.3617189e+08 | BD71: 1.2467206e+08 | BE71: 84743302 | BF71: 1.0180494e+08 | BG71: 1.2639505e+08 | BH71: 1.2980802e+08 | BI71: 1.2383319e+08 | BJ71: 1.3116252e+08 | BK71: 1.4497984e+08 | BL71: 1.3467316e+08 | BM71: 1.8032839e+08 | BN71: 1.5638179e+09
B72: Los Ríos | C72: 1.4524556e+08 | D72: 1.3617189e+08 | E72: 1.2467206e+08 | F72: 84743302 | G72: 1.0180494e+08 | H72: 1.2639505e+08 | I72: 1.2980802e+08 | J72: 1.2383319e+08 | K72: 1.3116252e+08 | L72: 1.4497984e+08 | M72: 1.3467316e+08 | N72: 1.8032839e+08 | O72: 1.5638179e+09 | P72: 1.3031816e+08 | Q72: 0.045780371 | BA72: Azuay | BB72: 1.6880606e+08 | BC72: 1.5787865e+08 | BD72: 1.1995637e+08 | BE72: 74015293 | BF72: 84732247 | BG72: 1.133051e+08 | BH72: 1.5075109e+08 | BI72: 1.2817287e+08 | BJ72: 1.5944355e+08 | BK72: 1.4126145e+08 | BL72: 1.30207e+08 | BM72: 1.6204825e+08 | BN72: 1.5905779e+09
B73: El Oro | C73: 1.6032168e+08 | D73: 1.4506822e+08 | E73: 1.2886033e+08 | F73: 79049263 | G73: 91973016 | H73: 1.1328837e+08 | I73: 1.2523801e+08 | J73: 1.2027492e+08 | K73: 1.3068392e+08 | L73: 1.4078513e+08 | M73: 1.2938463e+08 | N73: 1.6969613e+08 | O73: 1.5346236e+09 | P73: 1.278853e+08 | Q73: 0.044925715 | BA73: Resto de Provincias | BB73: 1.1139791e+09 | BC73: 1.0381067e+09 | BD73: 8.5839183e+08 | BE73: 5.2579671e+08 | BF73: 6.1980995e+08 | BG73: 7.8861855e+08 | BH73: 8.5679101e+08 | BI73: 8.5964406e+08 | BJ73: 9.3065313e+08 | BK73: 9.7095118e+08 | BL73: 8.8829954e+08 | BM73: 1.1536464e+09 | BN73: 1.0604688e+10
B74: Santo Domingo de los Tsáchilas | C74: 1.1651702e+08 | D74: 1.1129202e+08 | E74: 91441944 | F74: 53930939 | G74: 65270382 | H74: 87074291 | I74: 93289726 | J74: 92428070 | K74: 1.0103065e+08 | L74: 1.1142693e+08 | M74: 1.0752305e+08 | N74: 1.2635123e+08 | O74: 1.1575762e+09 | P74: 96464687 | Q74: 0.03388775 | BA74: El Oro | BB74: 1.6032168e+08 | BC74: 1.4506822e+08 | BD74: 1.2886033e+08 | BE74: 79049263 | BF74: 91973016 | BG74: 1.1328837e+08 | BH74: 1.2523801e+08 | BI74: 1.2027492e+08 | BJ74: 1.3068392e+08 | BK74: 1.4078513e+08 | BL74: 1.2938463e+08 | BM74: 1.6969613e+08 | BN74: 1.5346236e+09
B75: Tungurahua | C75: 1.2411986e+08 | D75: 1.1291764e+08 | E75: 90522882 | F75: 53650418 | G75: 62737295 | H75: 80032611 | I75: 86035264 | J75: 91774458 | K75: 95664941 | L75: 1.0222023e+08 | M75: 94916351 | N75: 1.2816876e+08 | O75: 1.1227607e+09 | P75: 93563392 | Q75: 0.032868534 | BA75: Santo Domingo de los Tsáchilas | BB75: 1.1651702e+08 | BC75: 1.1129202e+08 | BD75: 91441944 | BE75: 53930939 | BF75: 65270382 | BG75: 87074291 | BH75: 93289726 | BI75: 92428070 | BJ75: 1.0103065e+08 | BK75: 1.1142693e+08 | BL75: 1.0752305e+08 | BM75: 1.2635123e+08 | BN75: 1.1575762e+09
B76: Imbabura | C76: 95238118 | D76: 88654427 | E76: 69522113 | F76: 41511331 | G76: 47778289 | H76: 64123274 | I76: 71997027 | J76: 74456603 | K76: 79328229 | L76: 83735745 | M76: 76706054 | N76: 99663685 | O76: 8.9271489e+08 | P76: 74392908 | Q76: 0.026134001 | BA76: Tungurahua | BB76: 1.2411986e+08 | BC76: 1.1291764e+08 | BD76: 90522882 | BE76: 53650418 | BF76: 62737295 | BG76: 80032611 | BH76: 86035264 | BI76: 91774458 | BJ76: 95664941 | BK76: 1.0222023e+08 | BL76: 94916351 | BM76: 1.2816876e+08 | BN76: 1.1227607e+09
B77: Esmeraldas | C77: 74612793 | D77: 74272460 | E77: 63858519 | F77: 43623251 | G77: 52954378 | H77: 61605694 | I77: 64205966 | J77: 62930107 | K77: 67500422 | L77: 78362839 | M77: 64622533 | N77: 97826066 | O77: 8.0637503e+08 | P77: 67197919 | Q77: 0.023606424 | BA77: Imbabura | BB77: 95238118 | BC77: 88654427 | BD77: 69522113 | BE77: 41511331 | BF77: 47778289 | BG77: 64123274 | BH77: 71997027 | BI77: 74456603 | BJ77: 79328229 | BK77: 83735745 | BL77: 76706054 | BM77: 99663685 | BN77: 8.9271489e+08
B78: Loja | C78: 97655544 | D78: 91119142 | E78: 73177235 | F78: 39200584 | G78: 45637626 | H78: 63783777 | I78: 69282264 | J78: 66665724 | K78: 74895139 | L78: 51014331 | M78: 47718782 | N78: 65086571 | O78: 7.8523672e+08 | P78: 65436393 | Q78: 0.022987605 | BA78: Esmeraldas | BB78: 74612793 | BC78: 74272460 | BD78: 63858519 | BE78: 43623251 | BF78: 52954378 | BG78: 61605694 | BH78: 64205966 | BI78: 62930107 | BJ78: 67500422 | BK78: 78362839 | BL78: 64622533 | BM78: 97826066 | BN78: 8.0637503e+08
B79: Cotopaxi | C79: 74803759 | D79: 69557103 | E79: 58545478 | F79: 35856320 | G79: 40321810 | H79: 50296561 | I79: 57250838 | J79: 59741802 | K79: 63647744 | L79: 70714252 | M79: 63180121 | N79: 82274160 | O79: 7.2618995e+08 | P79: 60515829 | Q79: 0.021259026 | BA79: Loja | BB79: 97655544 | BC79: 91119142 | BD79: 73177235 | BE79: 39200584 | BF79: 45637626 | BG79: 63783777 | BH79: 69282264 | BI79: 66665724 | BJ79: 74895139 | BK79: 51014331 | BL79: 47718782 | BM79: 65086571 | BN79: 7.8523672e+08
... B92: Total | C92: 3.5410659e+09 | D92: 3.3005592e+09 | E92: 2.7782638e+09 | F92: 1.7651048e+09 | G92: 2.0501476e+09 | H92: 2.55783e+09 | I92: 2.7437331e+09 | J92: 2.7246167e+09 | K92: 2.9052076e+09 | L92: 3.0969903e+09 | M92: 2.8566374e+09 | N92: 3.8389795e+09 | O92: 3.4159136e+10 | P92: 2.8465947e+09 | Q92: 1 | BA92: Morona Santiago | BB92: 9410213.4 | BC92: 8839599.2 | BD92: 6801497.5 | BE92: 4140721.2 | BF92: 4728972 | BG92: 6414356.3 | BH92: 7328273.7 | BI92: 7697581.8 | BJ92: 8743973.9 | BK92: 7857176.7 | BL92: 7544074.9 | BM92: 8869788.1 | BN92: 88376229
BA93: Total | BB93: 3.5410659e+09 | BC93: 3.3005592e+09 | BD93: 2.7782638e+09 | BE93: 1.7651048e+09 | BF93: 2.0501476e+09 | BG93: 2.55783e+09 | BH93: 2.7437331e+09 | BI93: 2.7246167e+09 | BJ93: 2.9052076e+09 | BK93: 3.0969903e+09 | BL93: 2.8566374e+09 | BM93: 3.8389795e+09 | BN93: 3.4159136e+10
...

Sheet SECCIÓN V
B1: SUPERINTENDENCIA DE BANCOS DEL ECUADOR INTENDENCIA NACIONAL DE RIESGOS Y ESTUDIOS DIRECCIÓN DE ESTUDIOS Y GESTIÓN DE LA INFORMACIÓN SUBDIRECCIÓN DE ESTADÍSTICAS Y ESTUDIOS
